Workbook

Sheet INSTRUCTIONS
B1: INSTRUCTIONS:
B4: STEP 1 | C4: DATA
B5: FALSE | C5: Enter all DESIGN & DATA COLLECTION amounts invoiced that applies to customer. Use as reference the Proposals & Invoices.
C6: If category does not applies to client, enter $0.
B7: FALSE | C7: PERMITS & SERVICE FEES:
C8: FALSE | D8: Permit Services: Enter Amount. Use as reference the Design Proposal.
C9: FALSE | D9: Permit 1: Select EXC CATEGORICA ($75) or REA/DEA ($4,500)
C10: FALSE | D10: Permit 3: Select $300
C11: FALSE | D11: Liability Insurance: Select $2,000
C12: FALSE | D12: Construction Inspection Fee: Enter Amount. Use as reference the Design Proposal.
B13: FALSE | C13: PRODUCT OVERVIEW:
C14: FALSE | D14: Qty of Product: Select Containers Qty that applies to the project.
C15: FALSE | D15: Margin %: Select the margin discussed with Project Owner.
C16: FALSE | D16: Product square ft: Enter product square footage. Use as reference the Design Plans.
B17: FALSE | C17: DESCRIPTION: Enter the product model
B20: STEP 2 | C20: PRODUCT LABOR & SUBCONTRACT
A21: VALIDATE | B21: FALSE | C21: SUBCONTRACTORS: Enter all QUOTE amounts accordingly
A22: VALIDATE | B22: FALSE | C22: LABOR: Enter & Review all planned hours
B25: STEP 3 | C25: PRODUCT PHASE 1-5
A26: VALIDATE | B26: FALSE | C26: Check all items that applies to the project. The unchecked items, please Enter 0 in quantities.
A27: DOORS & FINISHES | B27: FALSE | C27: Items with Notes: Verify and enter the qty (according to plans) & ther cost of the items that applies to the project.
B30: STEP 4 | C30: EXTERIOR & ADD-ONS
B31: FALSE | C31: Enter the category, description, resource, and quote amount accordingly
B32: FALSE | C32: Validate with project owner all the items that applies to the project.
B35: ESTIMATE
B36: FALSE | C36: Enter Client Name
B37: FALSE | C37: Enter Version
B38: FALSE | C38: Enter Model
B39: FALSE | C39: Update Deliverables
B40: FALSE | C40: Select Classification
B41: FALSE | C41: Select Project Description
B42: FALSE | C42: DESIGN & DATA COLLECTION: Select the dropdown that applies of each category
B43: FALSE | C43: PERMITS & SERVICE FEES: Select the dropdown that applies of each category
B44: FALSE | C44: EXTERIOR & ADD-ONS : Select the dropdown that applies of each category
B47: PRINTING
B48: FALSE | C48: Print: Workbook
B49: FALSE | C49: Selection: Estimate and WBS
B50: FALSE | C50: Paper Size: A3
B51: FALSE | C51: Page Orientation: Portrait
B52: FALSE | C52: Scale: Fit to width
...

Sheet DATA
B2: DESIGN & DATA COLLECTION
B3: Plans and Construction Documents | C3: 26500
B4: Soil Study | C4: 5179
B5: Survey and Topography | C5: 2220
B6: Bio-Garden Design | C6: 0
B7: Solar System Design | C7: 0
B9: PERMITS & SERVICE FEES
B10: Municipal Patent | C10: =C30*0.05 -> 13094.883 | E10: Permits
B11: Permit Services (First 50%) | C11: =E11/2 -> 2250 | E11: 4500 | G11: ENTER TOTAL
B12: Permit Services (Last 50%) | C12: =E11/2 -> 2250 | G12: QUOTE AMOUNT
B13: State Insurance Fund | C13: =(DATA!C27/100)*5.65 -> 2661.15
B14: Permit 1 (Ex. Categórica or REA/DEA) | C14: 75
B15: Permit 2 (Construction) | C15: =SUM('PROJECT ESTIMATE'!F26:F27)*0.00635 -> 2898.6332
B16: Permit 3 (Use) | C16: 300
B17: Liability Insurance | C17: 0
B18: Construction Inspection Fee | C18: 9000
B20: PRODUCT OVERVIEW:
B21: Qty of Product | C21: 3
B22: Margin % | C22: 1.2
B23: Contingency % | C23: =IFERROR(VLOOKUP('PROJECT ESTIMATE'!C13,DATA!B35:C38,2,FALSE),"-") -> 1.15
B24: Foundation | C24: =IFERROR(VLOOKUP(B24,'EXTERIOR & ADD-ONS'!B3:F20,4,FALSE),"-") -> 55000
B25: Steel Structure | C25: =IFERROR(VLOOKUP(B25,'EXTERIOR & ADD-ONS'!B4:F21,4,FALSE),"-") -> 40000
B26: Subcontracted | C26: =SUMIF('PRODUCT PHASES 1-5'!$F$1:$J$90,"Subcontracted",'PRODUCT PHASES 1-5'!$J$1:$J$90) -> 126700
B27: Labor | C27: =SUMIF('PRODUCT PHASES 1-5'!$F$1:$J$90,"Labor",'PRODUCT PHASES 1-5'!$J$1:$J$90) -> 47100
B28: Materials | C28: =SUMIF('PRODUCT PHASES 1-5'!$F$1:$J$90,"Materials",'PRODUCT PHASES 1-5'!$J$1:$J$90) -> 51448.051
B29: Product Cost | C29: =SUM(C26:C28) -> 225248.05 | D29: =C30-C29 -> 36649.61
B30: Product Price | C30: ='PROJECT ESTIMATE'!F64 -> 261897.66
B31: Product square ft | C31: 0
B32: Cost per square ft | C32: =IFERROR(C31/C30,"-") -> 0
B34: CLASSIFICATION
B35: Paint by Numbers | C35: 1.05 | D35: [LOW RISK] KONTi and it's stakeholders are sure of what to do and how it is to be done. We feel confident on delivering the project early or under budget.
B36: Quest | C36: 1.1 | D36: [MEDIUM RISK] KONTi and it's stakeholders are sure of what should be done, but unsure how we will achieve it. This project will need a strick control of time and cost. May have cost and time overruns.
B37: Making a Movie | C37: 1.15 | D37: [MEDIUM RISK] KONTi and it's stakeholders are certain about how the project should proceed but not what needs to be done. Further definition may have cost and time overruns.
B38: Lost in the Fog | C38: 1.2 | D38: [HIGH RISK] KONTi and it's stakeholders do not know what you want or how to achieve it. This type of project is new for us, therefore has not been attempted before. High probability of cost and time changes.
B40: DESCRIPTION
B41: Containers | D41: The KONTi [ENTER MODEL] was designed for quick and simple container build and installation. Design specs, construction requirements, and build costs are standard. THIS IS A COST PLUS ESTIMATE AND IS SUBJECT TO CHANGE. | G41: ENTER MODEL
B42: Modulars | D42: The KONTi [ENTER MODEL] model was designed for a modular steel beam and post construction to be assembled on site. Design specs, construction requirements, and build costs are standard. THIS IS A COST PLUS ESTIMATE AND IS SUBJECT TO CHANGE.
B44: STAKEHOLDERS DATA
B45: Stakeholders | C45: Bill Rate | D45: Description
B46: Carla Gautier | C46: 75 | D46: Arquitect
...

Sheet PRODUCT LABOR & SUBCONTRACT
B1: Note: Data Entry All items that are in red. If a red item does not apply, ignore.
B2: SUBCONTRACTORS:
B3: Phases | C3: Category | D3: Description | E3: Resource | F3: ENTER QUOTE
B4: Phase 1 | C4: Container Purchase | D4: Purchase Container | E4: JF Broker Unlimited Corp | F4: 5000 | H4: Interior
B5: Phase 1 | C5: Container Purchase | D5: Transport Container to Shop | E5: MF Solution Corp | F5: 500 | H5: =30000+10000 -> 40000 | I5: ENTER TOTAL
B6: Phase 1 | C6: Structural Prep | D6: W&Ds framing cuts and installation | E6: Soldadura Rizoma | F6: 20000 | I6: QUOTE AMOUNT
B7: Phase 1 | C7: Structural Prep | D7: Container Reinforcement | E7: North Steel | F7: 7000
B8: Phase 1 | C8: Structural Prep | D8: Red Oxide Primer on container | E8: Edgardo Javier | F8: 400
B9: Phase 1 | C9: Structural Prep | D9: Container structural fumigation | E9: Jose Super Exterminating | F9: 500 | H9: W&D
B10: Phase 1 | C10: Exterior Windows & Doors | D10: Build | E10: Solid Doors | F10: =H10/2 -> 7500 | H10: 15000 | I10: ENTER TOTAL
B11: Phase 2 | C11: Exterior Windows & Doors | D11: Installation | E11: Solid Doors | F11: =H10/2 -> 7500 | I11: QUOTE AMOUNT
B12: Phase 2 | C12: Container Infrastructure | D12: Plumbing | E12: Henry Mercedes | F12: =3000+2200 -> 5200
B13: Phase 2 | C13: Container Infrastructure | D13: Electrical | E13: Geraldo Velez | F13: =5000+1600+1600+1600 -> 9800
B14: Phase 2 | C14: Container Infrastructure | D14: Interior | E14: Henry Mercedes | F14: =H5*0.5 -> 20000 | H14: Kitchen
B15: Phase 2 | C15: Kitchen | D15: Build | E15: AR Construction | F15: =H15/2 -> 7500 | H15: 15000 | I15: ENTER TOTAL
B16: Phase 3 | C16: Kitchen | D16: Installation | E16: AR Construction | F16: =H15/2 -> 7500 | I16: QUOTE AMOUNT
B17: Phase 3 | C17: Interior Build | D17: Plumbing Finishes | E17: Henry Mercedes | F17: 500
B18: Phase 3 | C18: Interior Build | D18: AC units Installation | E18: D&G Air Conditioning | F18: 2200
B19: Phase 3 | C19: Interior Build | D19: Interior | E19: Henry Mercedes | F19: =H5*0.25 -> 10000
B20: Phase 3 | C20: Bathroom | D20: Bathroom Build | E20: Henry Mercedes | F20: 6000
B21: Phase 4 | C21: Container Finishes | D21: Electrical finishes | E21: Geraldo Velez | F21: 1000
B22: Phase 4 | C22: Container Finishes | D22: Interior | E22: Henry Mercedes | F22: =H5*0.25 -> 10000
B23: Phase 4 | C23: Container Finishes | D23: Exterior Painting | E23: Edgardo Javier | F23: 400
B24: Phase 4 | C24: Container Installation | D24: Transport Container to Site | E24: MF Solution Corp | F24: 15000
B25: Phase 5 | C25: Container Installation | D25: Welding | E25: Soldadura Rizoma | F25: 3000
B26: Phase 5 | C26: Detailing | D26: Door Installation | F26: 3000
B27: Phase 5 | C27: Post Construction Cleanup | D27: Last Clean Up | F27: 2000
H28: Enter Hrs & Review
B29: LABOR:
B30: Phases | C30: Category | D30: Description | E30: Resource | F30: Bill Rate | G30: Planned Hrs | H30: Total Cost
B31: Phase 1 | C31: Container Purchase | D31: Project Management | F31: =IFERROR(VLOOKUP(E31,DATA!$B$45:$C$48,2,FALSE),0) -> 0 | G31: 0 | H31: =G31*F31 -> 0
B32: Phase 1 | C32: Container Purchase | D32: Coordination | F32: =IFERROR(VLOOKUP(E32,DATA!$B$45:$C$48,2,FALSE),0) -> 0 | G32: 0 | H32: =G32*F32 -> 0
B33: Phase 1 | C33: Structural Prep | D33: Project Management | F33: =IFERROR(VLOOKUP(E33,DATA!$B$45:$C$48,2,FALSE),0) -> 0 | G33: 0 | H33: =G33*F33 -> 0
B34: Phase 1 | C34: Structural Prep | D34: Coordination | F34: =IFERROR(VLOOKUP(E34,DATA!$B$45:$C$48,2,FALSE),0) -> 0 | G34: 0 | H34: =G34*F34 -> 0
B35: Phase 1 | C35: Structural Prep | D35: Punch List | F35: =IFERROR(VLOOKUP(E35,DATA!$B$45:$C$48,2,FALSE),0) -> 0 | G35: 0 | H35: =G35*F35 -> 0
B36: Phase 1 | C36: Structural Prep | D36: Structural Paint & Sealing | F36: =IFERROR(VLOOKUP(E36,DATA!$B$45:$C$48,2,FALSE),0) -> 0 | G36: 0 | H36: =G36*F36 -> 0
B37: Phase 1 | C37: Structural Prep | D37: Structural Paint & Sealing | F37: =IFERROR(VLOOKUP(E37,DATA!$B$45:$C$48,2,FALSE),0) -> 0 | G37: 0 | H37: =G37*F37 -> 0
B38: Phase 1 | C38: Exterior Windows & Doors | D38: Project Management | F38: =IFERROR(VLOOKUP(E38,DATA!$B$45:$C$48,2,FALSE),0) -> 0 | G38: 0 | H38: =G38*F38 -> 0
B39: Phase 1 | C39: Exterior Windows & Doors | D39: Coordination | F39: =IFERROR(VLOOKUP(E39,DATA!$B$45:$C$48,2,FALSE),0) -> 0 | G39: 0 | H39: =G39*F39 -> 0
B40: Phase 2 | C40: Exterior Windows & Doors | D40: Project Management | F40: =IFERROR(VLOOKUP(E40,DATA!$B$45:$C$48,2,FALSE),0) -> 0 | G40: 0 | H40: =G40*F40 -> 0
...

Sheet PRODUCT PHASES 1-5
A1: Phases | C1: Category | D1: Description | E1: Stakeholder | F1: Class | G1: Qty | H1: Cost | I1: Total Cost | J1: Product Cost
A2: Phase 1 | B2: TRUE | C2: Container Purchase | D2: Purchase Container | E2: JF Broker Unlimited Corp | F2: Subcontracted | G2: 1 | H2: ='PRODUCT LABOR & SUBCONTRACT'!F4 -> 5000 | I2: =H2*G2 -> 5000 | J2: =I2*DATA!$C$21 -> 15000
A3: Phase 1 | B3: TRUE | C3: Container Purchase | D3: Transport Container to Shop | E3: MF Solution Corp | F3: Subcontracted | G3: 1 | H3: ='PRODUCT LABOR & SUBCONTRACT'!F5 -> 500 | I3: =H3*G3 -> 500 | J3: =I3*DATA!$C$21 -> 1500
A4: Phase 1 | B4: TRUE | C4: Container Purchase | D4: Coordination | E4: Konti Design | F4: Labor | G4: 1 | H4: 500 | I4: =H4*G4 -> 500 | J4: =I4 -> 500
A5: Phase 1 | B5: TRUE | C5: Structural Prep | D5: Container Reinforcement | E5: North Steel | F5: Subcontracted | G5: 1 | H5: ='PRODUCT LABOR & SUBCONTRACT'!F7 -> 7000 | I5: =H5*G5 -> 7000 | J5: =I5 -> 7000
A6: Phase 1 | B6: TRUE | C6: Structural Prep | D6: W&Ds framing cuts and installation | E6: North Steel | F6: Subcontracted | G6: 1 | H6: ='PRODUCT LABOR & SUBCONTRACT'!F6 -> 20000 | I6: =H6*G6 -> 20000 | J6: =I6 -> 20000
A7: Phase 1 | B7: TRUE | C7: Structural Prep | D7: Acrylic Clear Primer & Sealer on frames, and Red Oxide Primer on container | E7: Konti Design | F7: Labor | G7: 1 | H7: ='PRODUCT LABOR & SUBCONTRACT'!F8 -> 400 | I7: =H7*G7 -> 400 | J7: =I7*DATA!$C$21 -> 1200
A8: Phase 1 | B8: TRUE | C8: Structural Prep | D8: Purchase of AS-210 1 Gal. 100% Acrylic Clear Primer and Sealer | E8: Konti Design | F8: Materials | G8: 1 | H8: 17 | I8: =(H8*G8)*1.115 -> 18.955 | J8: =I8*DATA!$C$21 -> 56.865
A9: Phase 1 | B9: TRUE | C9: Structural Prep | D9: Purchase of 1 Gal. Oil Red Oxide Metal Primer | E9: Konti Design | F9: Materials | G9: 2 | H9: 100 | I9: =(H9*G9)*1.115 -> 223 | J9: =I9*DATA!$C$21 -> 669
A10: Phase 1 | B10: TRUE | C10: Structural Prep | D10: Miscellenous Materials | E10: Konti Design | F10: Materials | G10: 1 | H10: 500 | I10: =(H10*G10)*1.115 -> 557.5 | J10: =I10*DATA!$C$21 -> 1672.5
A11: Phase 1 | B11: TRUE | C11: Structural Prep | D11: Container structural fumigation | E11: Jose Super Exterminating | F11: Subcontracted | G11: 1 | H11: ='PRODUCT LABOR & SUBCONTRACT'!F9 -> 500 | I11: =H11*G11 -> 500 | J11: =I11*DATA!$C$21 -> 1500
A12: Phase 1 | B12: TRUE | C12: Structural Prep | D12: Coordination | E12: Konti Design | F12: Labor | G12: 1 | H12: 500 | I12: =H12*G12 -> 500 | J12: =I12 -> 500
A13: Phase 1 | B13: TRUE | C13: Exterior Windows & Doors | D13: First 50% deposit to start manufacturing | E13: Solid Doors | F13: Subcontracted | G13: 1 | H13: ='PRODUCT LABOR & SUBCONTRACT'!F10 -> 7500 | I13: =H13*G13 -> 7500 | J13: =I13 -> 7500
A14: Phase 1 | B14: TRUE | C14: Exterior Windows & Doors | D14: Coordination | E14: Konti Design | F14: Labor | G14: 1 | H14: 500 | I14: =H14*G14 -> 500 | J14: =I14 -> 500
A15: Phase 2 | B15: TRUE | C15: Exterior Windows & Doors | D15: Installation | E15: Solid Doors | F15: Subcontracted | G15: 1 | H15: ='PRODUCT LABOR & SUBCONTRACT'!F11 -> 7500 | I15: =H15*G15 -> 7500 | J15: =I15 -> 7500
A16: Phase 2 | B16: TRUE | C16: Exterior Windows & Doors | D16: Coordination | E16: Konti Design | F16: Labor | G16: 1 | H16: 500 | I16: =H16*G16 -> 500 | J16: =I16 -> 500
A17: Phase 2 | B17: TRUE | C17: Container Infrastructure | D17: Labor for Wall Infrastructure | E17: Konti Design | F17: Labor | G17: 1 | H17: ='PRODUCT LABOR & SUBCONTRACT'!F14 -> 20000 | I17: =H17*G17 -> 20000 | J17: =I17 -> 20000
A18: Phase 2 | B18: TRUE | C18: Container Infrastructure | D18: Studs 20GA 3 - 5/8 x 10 (Wall Divisions) | E18: Konti Design | F18: Materials | G18: 25 | H18: 10.75 | I18: =(H18*G18)*1.115 -> 299.65625 | J18: =I18*DATA!$C$21 -> 898.96875
A19: Phase 2 | B19: TRUE | C19: Container Infrastructure | D19: Studs 20GA 2 1/2 x 10 (Walls) | E19: Konti Design | F19: Materials | G19: 80 | H19: 7.2 | I19: =(H19*G19)*1.115 -> 642.24 | J19: =I19*DATA!$C$21 -> 1926.72
A20: Phase 2 | B20: TRUE | C20: Container Infrastructure | D20: Studs 20GA 2 1/2 x 8 (Ceiling) | E20: Konti Design | F20: Materials | G20: 30 | H20: 6.05 | I20: =(H20*G20)*1.115 -> 202.3725 | J20: =I20*DATA!$C$21 -> 607.1175
A21: Phase 2 | B21: TRUE | C21: Container Infrastructure | D21: Tracks 20GA 2 1/2 x 10 | E21: Konti Design | F21: Materials | G21: 25 | H21: 7.2 | I21: =(H21*G21)*1.115 -> 200.7 | J21: =I21*DATA!$C$21 -> 602.1
A22: Phase 2 | B22: TRUE | C22: Container Infrastructure | D22: Tracks 20GA 3 - 5/8 x 10 | E22: Konti Design | F22: Materials | G22: 10 | H22: 10.75 | I22: =(H22*G22)*1.115 -> 119.8625 | J22: =I22*DATA!$C$21 -> 359.5875
A23: Phase 2 | B23: TRUE | C23: Container Infrastructure | D23: Tracks & Studs Transportation | E23: Konti Design | F23: Materials | G23: 1 | H23: 100 | I23: =(H23*G23)*1.115 -> 111.5 | J23: =I23*DATA!$C$21 -> 334.5
A24: Phase 2 | B24: TRUE | C24: Container Infrastructure | D24: 3/4 in. x 4 ft. x 8 ft. Pine Pressure-Treated Plywood (Blockings) | E24: Konti Design | F24: Materials | G24: 5 | H24: 56.9 | I24: =(H24*G24)*1.115 -> 317.2175 | J24: =I24*DATA!$C$21 -> 951.6525
A25: Phase 2 | B25: TRUE | C25: Container Infrastructure | D25: 2 in x 4 in x 8 ft. Pine Pressure-Treated Wood (Interior Doors Post) | E25: Konti Design | F25: Materials | G25: 10 | H25: 7 | I25: =(H25*G25)*1.115 -> 78.05 | J25: =I25*DATA!$C$21 -> 234.15
A26: Phase 2 | B26: TRUE | C26: Container Infrastructure | D26: Insulation: Solar Guard RFSK/Foil 48"x125' (500sf) | E26: Konti Design | F26: Materials | G26: 2 | H26: 240 | I26: =(H26*G26)*1.115 -> 535.2 | J26: =I26*DATA!$C$21 -> 1605.6
A27: Phase 2 | B27: TRUE | C27: Container Infrastructure | D27: Miscellenous Materials | E27: Konti Design | F27: Materials | G27: 1 | H27: 600 | I27: =(H27*G27)*1.115 -> 669 | J27: =I27*DATA!$C$21 -> 2007
A28: Phase 2 | B28: TRUE | C28: Container Infrastructure | D28: Shower [TBD by client] | E28: Konti Design | F28: Materials | G28: 1 | H28: 300 | I28: =(H28*G28)*1.115 -> 334.5 | J28: =I28*DATA!$C$21 -> 1003.5
A29: Phase 2 | B29: TRUE | C29: Container Infrastructure | D29: Plumbing Infrastructure | E29: Elvis Colon | F29: Subcontracted | G29: 1 | H29: ='PRODUCT LABOR & SUBCONTRACT'!F12 -> 5200 | I29: =H29*G29 -> 5200 | J29: =I29 -> 5200
A30: Phase 2 | B30: TRUE | C30: Container Infrastructure | D30: Electrical Infrastructure | E30: Geraldo Velez | F30: Subcontracted | G30: 1 | H30: ='PRODUCT LABOR & SUBCONTRACT'!F13 -> 9800 | I30: =H30*G30 -> 9800 | J30: =I30 -> 9800
A31: Phase 2 | B31: TRUE | C31: Kitchen | D31: Coordination | E31: Konti Design | F31: Labor | G31: 1 | H31: 500 | I31: =H31*G31 -> 500 | J31: =I31 -> 500
A32: Phase 2 | B32: TRUE | C32: Kitchen | D32: Starts Kitchen Build | E32: AR Construction | F32: Subcontracted | G32: 1 | H32: ='PRODUCT LABOR & SUBCONTRACT'!F15 -> 7500 | I32: =H32*G32 -> 7500 | J32: =I32 -> 7500
A33: Phase 2 | B33: TRUE | C33: Kitchen | D33: Sink [TBD by client] | E33: Konti Design | F33: Materials | G33: 1 | H33: 235 | I33: =(H33*G33)*1.115 -> 262.025 | J33: =I33*DATA!$C$21 -> 786.075
A34: Phase 2 | B34: TRUE | C34: Kitchen | D34: Stove [TBD by client] | E34: Konti Design | F34: Materials | G34: 1 | H34: 170 | I34: =(H34*G34)*1.115 -> 189.55 | J34: =I34*DATA!$C$21 -> 568.65
A35: Phase 3 | B35: TRUE | C35: Interior Build | D35: Labor for Interior Build | E35: Konti Design | F35: Labor | G35: 1 | H35: ='PRODUCT LABOR & SUBCONTRACT'!F19 -> 10000 | I35: =H35*G35 -> 10000 | J35: =I35 -> 10000
A36: Phase 3 | B36: TRUE | C36: Interior Build | D36: Plumbing Finishes in Kitchen & Bathroom | E36: Elvis Colon | F36: Subcontracted | G36: 1 | H36: ='PRODUCT LABOR & SUBCONTRACT'!F17 -> 500 | I36: =H36*G36 -> 500 | J36: =I36*DATA!$C$21 -> 1500
A37: Phase 3 | B37: TRUE | C37: Interior Build | D37: AC units Installation | E37: D&G Air Conditioning | F37: Subcontracted | G37: 1 | H37: ='PRODUCT LABOR & SUBCONTRACT'!F18 -> 2200 | I37: =H37*G37 -> 2200 | J37: =I37 -> 2200
A38: Phase 3 | B38: TRUE | C38: Interior Build | D38: Drywall 4x10x5/8 (Walls) | E38: Konti Design | F38: Materials | G38: 30 | H38: 28 | I38: =(H38*G38)*1.115 -> 936.6 | J38: =I38*DATA!$C$21 -> 2809.8
A39: Phase 3 | B39: TRUE | C39: Interior Build | D39: Drywall 4x8x5/8 (Ceiling) | E39: Konti Design | F39: Materials | G39: 12 | H39: 23 | I39: =(H39*G39)*1.115 -> 307.74 | J39: =I39*DATA!$C$21 -> 923.22
A40: Phase 3 | B40: TRUE | C40: Interior Build | D40: Joint Compound Ultralight 4.5 GAL. | E40: Konti Design | F40: Materials | G40: 5 | H40: 25 | I40: =(H40*G40)*1.115 -> 139.375 | J40: =I40*DATA!$C$21 -> 418.125
...

Sheet EXTERIOR & ADD-ONS
B1: Note: Data Entry and classify items that applies to the Project, according to scope.
B2: EXTERIOR & ADD-ONS
B3: Category | C3: Description | D3: Stakeholder | E3: ENTER QUOTE | F3: BILL AMOUNT
B4: Foundation | C4: Considering High Phreatic Levels | D4: Henry Mercedes | E4: 55000 | F4: =E4*DATA!$C$22 -> 66000 | I4: 40 | J4: Job Days | L4: 50 | M4: gas
B5: Site Electric | C5: Pedestal and Connection | E5: =7500+3000 -> 10500 | F5: =E5*DATA!$C$22 -> 12600 | I5: =I4/5 -> 8 | J5: week | L5: 10 | M5: autoexpreso
B6: Site Plumbing | E6: 10000 | F6: =E6*DATA!$C$22 -> 12000 | I6: 12 | J6: weekly hrs | L6: 20 | M6: lunch
B7: Bio Garden | E7: 16650 | F7: =E7*DATA!$C$22 -> 19980 | I7: 50 | J7: rate | L7: =SUM(L4:L6) -> 80 | M7: Consumables
B8: Decking | C8: Surface | E8: 25000 | F8: =E8*DATA!$C$22 -> 30000 | I8: =I6*I7 -> 600 | J8: CM Cost Weekly | L8: =L7*I5 -> 640 | M8: Total Consumables
B9: Site Work | C9: Budget | E9: 5000 | F9: =E9*DATA!$C$22 -> 6000 | I9: =I8*I5 -> 4800 | J9: CM Cost Total | L9: =I9+L8 -> 5440 | M9: CM & Consumables
B10: Steel Structure | C10: Deck Structure | E10: 40000 | F10: =E10*DATA!$C$22 -> 48000
B11: Decking | C11: Wood Structure | E11: 15000 | F11: =E11*DATA!$C$22 -> 18000 | I11: 39000 | J11: Jose Perez
E12: 0 | F12: =E12*DATA!$C$22 -> 0 | I12: =L9 -> 5440 | J12: CM/Consumable
E13: 0 | F13: =E13*DATA!$C$22 -> 0 | I13: 0 | J13: Bathroom/Storage Rental
E14: 0 | F14: =E14*DATA!$C$22 -> 0 | I14: 5000 | J14: Relleno
E15: 0 | F15: =E15*DATA!$C$22 -> 0 | I15: 0 | J15: Airbnb
E16: 0 | F16: =E16*DATA!$C$22 -> 0 | I16: 1200 | J16: Survey Stakeout
E17: 0 | F17: =E17*DATA!$C$22 -> 0 | I17: =(E4)-I18 -> 4360 | J17: Contingency
E18: 0 | F18: =E18*DATA!$C$22 -> 0 | I18: =SUM(I11:I16) -> 50640 | J18: Total
E19: 0 | F19: =E19*DATA!$C$22 -> 0 | I19: =SUM(I17:I18) -> 55000 | J19: Total with Contingency
E20: 0 | F20: =E20*DATA!$C$22 -> 0
D26: =800*3 -> 2400 | E26: Transport to Site
D27: 2000 | E27: Grua
D28: =SUM(D26:D27) -> 4400 | E28: Total
D30: 15000 | E30: Presupuesto de Transporte
D32: =D30-D28 -> 10600 | E32: Remaining Budget for Lodging
D34: =650*12 -> 7800 | E34: Lodging
D35: =150*6 -> 900 | E35: Utilities
D37: =D32-D34-D35 -> 1900 | E37: Difference

Sheet PROJECT ESTIMATE
B2: PROJECT SCOPE OVERVIEW
C4: CLIENT | D4: Benito Colon | F4: DELIVERABLES:
C6: DATE | D6: =TODAY() -> 46043 | E6: TRUE | F6: Proposal
C8: VERSION | D8: 1 | E8: TRUE | F8: Design & Construction Docs
C10: PRODUCT MODEL | D10: L3 | E10: FALSE | F10: Product Delivery
C12: CLASSIFICATION:
C13: Making a Movie | D13: =VLOOKUP(C13,DATA!B35:D38,3,FALSE) -> [MEDIUM RISK] KONTi and it's stakeholders are certain about how the project should proceed but not what needs to be done. Further definition may have cost and time overruns.
C15: PROJECT DESCRIPTION:
C16: The KONTi L1 model was designed for quick and simple container build and installation. Design specs, construction requirements, and build costs are standard. THIS IS A COST PLUS ESTIMATE AND IS SUBJECT TO CHANGE.
C18: SUMMARY:
C19: ESTIMATED PROJECT COST | F19: =SUM(F24:F27) -> 522906.33
C20: PAID TO DATE | F20: =SUMIF(E38:G90,"Paid",F38:F90) -> 36149
C21: ESTIMATED PROJECT BALANCE | F21: =F19-F20 -> 486757.33
C23: ESTIMATED PROJECT COST BREAKDOWN:
C24: DESIGN AND DATA COLLECTION | F24: =F37 -> 33899
C25: PERMITS & SERVICE FEES | F25: =F45 -> 32529.666
C26: PRODUCT (CONTAINERS) | F26: =F64 -> 261897.66
C27: EXTERIOR & ADD-ONS | F27: =F77 -> 194580
C29: CONSTRUCTION CONTINGENCY | F29: =IFERROR(SUM(F26:F27)*(DATA!C23-1),"-") -> 68471.649
C30: Designated amount of money within a construction budget that is set aside to cover any unforseen costs, risks, events, or changes in scope that may affect the project's cost over the course of its life. This money is on reserve and is not allocated to any specific area of work. It is a form of risk management used to avoid cutting costs in other areas to keep the project's schedule and quality commitments. This contingency is intended to cover additional costs that might occur due to factors like design changes, unexpected site conditions, weather delays, or other unforeseen circumstances. Applies to Product (Containers) and Exterior & Add-ons.
B32: NOTE: THIS A COST-PLUS ESTIMATE AND IS SUBJECT TO CHANGE.
B34: PRE-CONSTRUCTION:
B37: DESIGN & DATA COLLECTION | F37: =SUM(F38:F42) -> 33899
C38: Plans and Construction Documents | E38: PAID | F38: =DATA!C3 -> 26500
C39: Soil Study | E39: PAID | F39: =DATA!C4 -> 5179
C40: Survey and Topography | E40: PAID | F40: =DATA!C5 -> 2220
C41: Bio-Garden Design | E41: N/A | F41: =DATA!C6 -> 0
C42: Solar System Design | E42: N/A | F42: =DATA!C7 -> 0
B45: PERMITS & SERVICE FEES | F45: =SUM(F46:F54) -> 32529.666
C46: Municipal Patent (5%) | E46: UPON APPROVAL | F46: =DATA!C10 -> 13094.883
C47: Permit Services (First 50%) | E47: PAID | F47: =DATA!C11 -> 2250
C48: Permit Services (Last 50%) | E48: PENDING | F48: =DATA!C12 -> 2250
C49: State Insurance Fund | E49: UPON APPROVAL | F49: =DATA!C13 -> 2661.15
C50: Permit 1 (Ex. Categórica) | E50: PENDING | F50: =DATA!C14 -> 75
C51: Permit 2 (Construction) | E51: UPON APPROVAL | F51: =DATA!C15 -> 2898.6332
C52: Permit 3 (Use) | E52: UPON APPROVAL | F52: =DATA!C16 -> 300
C53: Liability Insurance | E53: UPON APPROVAL | F53: =DATA!C17 -> 0
C54: Construction Inspection Fee | E54: UPON APPROVAL | F54: =DATA!C18 -> 9000
B59: NOTE: THIS A COST-PLUS ESTIMATE AND IS SUBJECT TO CHANGE.
B61: CONSTRUCTION:
...

Sheet PROJECT ESTIMATE Wood Deck
B2: PROJECT SCOPE OVERVIEW
C4: CLIENT | D4: Benito Colon | F4: DELIVERABLES:
C6: DATE | D6: =TODAY() -> 46043 | E6: TRUE | F6: Proposal
C8: VERSION | D8: 2 | E8: TRUE | F8: Design & Construction Docs
C10: PRODUCT MODEL | D10: L3 | E10: FALSE | F10: Product Delivery
C12: CLASSIFICATION:
C13: Making a Movie | D13: =VLOOKUP(C13,DATA!B35:D38,3,FALSE) -> [MEDIUM RISK] KONTi and it's stakeholders are certain about how the project should proceed but not what needs to be done. Further definition may have cost and time overruns.
C15: PROJECT DESCRIPTION:
C16: The KONTi L1 model was designed for quick and simple container build and installation. Design specs, construction requirements, and build costs are standard. THIS IS A COST PLUS ESTIMATE AND IS SUBJECT TO CHANGE.
C18: SUMMARY:
C19: ESTIMATED PROJECT COST | F19: =SUM(F24:F27) -> 492906.33
C20: PAID TO DATE | F20: =SUMIF(E38:G90,"Paid",F38:F90) -> 36149
C21: ESTIMATED PROJECT BALANCE | F21: =F19-F20 -> 456757.33
C23: ESTIMATED PROJECT COST BREAKDOWN:
C24: DESIGN AND DATA COLLECTION | F24: =F37 -> 33899
C25: PERMITS & SERVICE FEES | F25: =F45 -> 32529.666
C26: PRODUCT (CONTAINERS) | F26: =F64 -> 261897.66
C27: EXTERIOR & ADD-ONS | F27: =F77 -> 164580
C29: CONSTRUCTION CONTINGENCY | F29: =IFERROR(SUM(F26:F27)*(DATA!C23-1),"-") -> 63971.649
C30: Designated amount of money within a construction budget that is set aside to cover any unforseen costs, risks, events, or changes in scope that may affect the project's cost over the course of its life. This money is on reserve and is not allocated to any specific area of work. It is a form of risk management used to avoid cutting costs in other areas to keep the project's schedule and quality commitments. This contingency is intended to cover additional costs that might occur due to factors like design changes, unexpected site conditions, weather delays, or other unforeseen circumstances. Applies to Product (Containers) and Exterior & Add-ons.
B32: NOTE: THIS A COST-PLUS ESTIMATE AND IS SUBJECT TO CHANGE.
B34: PRE-CONSTRUCTION:
B37: DESIGN & DATA COLLECTION | F37: =SUM(F38:F42) -> 33899
C38: Plans and Construction Documents | E38: PAID | F38: =DATA!C3 -> 26500
C39: Soil Study | E39: PAID | F39: =DATA!C4 -> 5179
C40: Survey and Topography | E40: PAID | F40: =DATA!C5 -> 2220
C41: Bio-Garden Design | E41: N/A | F41: =DATA!C6 -> 0
C42: Solar System Design | E42: N/A | F42: =DATA!C7 -> 0
B45: PERMITS & SERVICE FEES | F45: =SUM(F46:F54) -> 32529.666
C46: Municipal Patent (5%) | E46: UPON APPROVAL | F46: =DATA!C10 -> 13094.883
C47: Permit Services (First 50%) | E47: PAID | F47: =DATA!C11 -> 2250
C48: Permit Services (Last 50%) | E48: PENDING | F48: =DATA!C12 -> 2250
C49: State Insurance Fund | E49: UPON APPROVAL | F49: =DATA!C13 -> 2661.15
C50: Permit 1 (Ex. Categórica) | E50: PENDING | F50: =DATA!C14 -> 75
C51: Permit 2 (Construction) | E51: UPON APPROVAL | F51: =DATA!C15 -> 2898.6332
C52: Permit 3 (Use) | E52: UPON APPROVAL | F52: =DATA!C16 -> 300
C53: Liability Insurance | E53: UPON APPROVAL | F53: =DATA!C17 -> 0
C54: Construction Inspection Fee | E54: UPON APPROVAL | F54: =DATA!C18 -> 9000
B59: NOTE: THIS A COST-PLUS ESTIMATE AND IS SUBJECT TO CHANGE.
B61: CONSTRUCTION:
...

Sheet CONTAINERS ESTIMATE
B2: PROJECT SCOPE OVERVIEW
C5: CLIENT | D5: Frances Cartagena | F5: DELIVERABLES:
C7: DATE | D7: =TODAY() -> 46043 | E7: TRUE | F7: Proposal
C9: VERSION | D9: 3 | E9: TRUE | F9: Design & Construction Docs
C11: PRODUCT MODEL | D11: L3 | E11: FALSE | F11: Product Delivery
C13: CLASSIFICATION:
C14: Quest | D14: =VLOOKUP(C14,DATA!B35:D38,3,FALSE) -> [MEDIUM RISK] KONTi and it's stakeholders are sure of what should be done, but unsure how we will achieve it. This project will need a strick control of time and cost. May have cost and time overruns.
C16: PROJECT DESCRIPTION:
C17: The KONTi L3 model was designed for quick and simple container build and installation. Design specs, construction requirements, and build costs are standard. THIS IS A COST PLUS ESTIMATE AND IS SUBJECT TO CHANGE.
C20: TOTAL ESTIMATED PROJECT COST | F20: =SUM(E23:E26) -> 328326.33
C21: PAID TO DATE | F21: =SUMIF(E38:G96,"Paid",F38:F96) -> 36224
C22: ESTIMATED PROJECT BALANCE | F22: =F20-F21 -> 292102.33
C23: DESIGN AND DATA COLLECTION | E23: =F37 -> 33899
C24: PERMITS & SERVICE FEES | E24: =F45 -> 32529.666
C25: PRODUCT (CONTAINERS) | E25: =F70 -> 261897.66
C26: EXTERIOR & ADD-ONS | E26: =F83 -> 0
C28: CONSTRUCTION CONTINGENCY | F28: =IFERROR(SUM(E25:E26)*(DATA!C23-1),"-") -> 39284.649
C29: Designated amount of money within a construction budget that is set aside to cover any unforseen costs, risks, events, or changes in scope that may affect the project's cost over the course of its life. This money is on reserve and is not allocated to any specific area of work. It is a form of risk management used to avoid cutting costs in other areas to keep the project's schedule and quality commitments. This contingency is intended to cover additional costs that might occur due to factors like design changes, unexpected site conditions, weather delays, or other unforeseen circumstances.
B31: NOTE: THIS A COST-PLUS ESTIMATE AND IS SUBJECT TO CHANGE.
B34: PRE-CONSTRUCTION:
C37: DESIGN & DATA COLLECTION | F37: =SUM(F38:F42) -> 33899
C38: Plans and Construction Documents | E38: PAID | F38: =DATA!C3 -> 26500
C39: Soil Study | E39: PAID | F39: =DATA!C4 -> 5179
C40: Survey and Topography | E40: PAID | F40: =DATA!C5 -> 2220
C41: Bio-Garden Design | E41: N/A | F41: =DATA!C6 -> 0
C42: Solar System Design | E42: PAID | F42: =DATA!C7 -> 0
C45: PERMITS & SERVICE FEES | F45: =SUM(F46:F54) -> 32529.666
C46: Municipal Patent (5%) | E46: UPON APPROVAL | F46: =DATA!C10 -> 13094.883
C47: Permit Services (First 50%) | E47: PAID | F47: =DATA!C11 -> 2250
C48: Permit Services (Last 50%) | E48: PENDING | F48: =DATA!C12 -> 2250
C49: State Insurance Fund | E49: UPON APPROVAL | F49: =DATA!C13 -> 2661.15
C50: Permit 1 (Ex. Categórica) | E50: PAID | F50: =DATA!C14 -> 75
C51: Permit 2 (Construction) | E51: UPON APPROVAL | F51: =DATA!C15 -> 2898.6332
C52: Permit 3 (Use) | E52: UPON APPROVAL | F52: =DATA!C16 -> 300
C53: Liability Insurance | E53: UPON APPROVAL | F53: =DATA!C17 -> 0
C54: Construction Inspection Fee | E54: UPON APPROVAL | F54: =DATA!C18 -> 9000
B65: NOTE: THIS A COST-PLUS ESTIMATE AND IS SUBJECT TO CHANGE.
B67: CONSTRUCTION:
C70: PRODUCT (CONTAINERS) | F70: =SUM(F71:F81) -> 261897.66
C71: Container Purchase | E71: Phase 1 | F71: =SUM('PRODUCT PHASES 1-5'!J2:J4)*DATA!C22 -> 20400
...

Sheet WBS
B1: WORK BREAKDOWN STRUCTURE (WBS)
B2: Phase: Containers Build
B3: Project Owner | D3: Project Manager | F3: Construction Manager
B4: Carla Gautier | D4: Jorge Rosa | F4: Andrea Camacho
B6: =PRESENTATION!D6 -> 60718.038 | D6: =PRESENTATION!D12 -> 64237.075 | F6: =PRESENTATION!D17 -> 58066.497 | H6: =PRESENTATION!D23 -> 57226.971 | J6: =PRESENTATION!D29 -> 21649.08
B7: PHASE #1 | D7: PHASE #2 | F7: PHASE #3 | H7: PHASE #4 | J7: PHASE #5
B9: 1.1 Container Purchase | D9: 2.1 Infrastructure | F9: 3.1 Interior Build | H9: 4.1 Kitchen | J9: 5.1 Detailing
B10: - | C10: Purchase of Container | D10: - | E10: Metal framing | F10: - | G10: Panels | H10: - | I10: Installation | J10: - | K10: Bathroom Furniture & Fixtures
B11: - | C11: Transport to shop | D11: - | E11: Insulation | F11: - | G11: Mudding & Sanding | H11: - | I11: Stove & Sink Installation | J11: - | K11: Toilet Purchase & Installation
B12: 1.2 Structural Prep | D12: - | E12: Blockings | F12: - | G12: Flooring | H12: 4.2 Finishes | J12: - | K12: Vanity Purchase & Installation
B13: - | C13: Frame & Cuts | D13: - | E13: Plumbing Infrastructure | F13: - | G13: AC Units (If applicable) | H13: - | I13: Ceiling Fan (If applicable) | J13: - | K13: Faucets Purchase & Installation
B14: - | C14: Frames Sealing | D14: - | E14: Electrical Infrastructure | F14: - | G14: Primer | H14: - | I14: Recessed Lights (If applicable) | J14: - | K14: Other Purchase & Installation
B15: - | C15: Red Oxide Primer | D15: - | E15: Gypsum Board Panels | F15: 3.2 Bathroom | H15: - | I15: Pendant Lamps | J15: - | K15: Interior Doors
B16: - | C16: Fumigation | D16: 2.2 Container Installation | F16: - | G16: Tiles | H16: - | I16: Interior Painting | J16: - | K16: Transportation fixes
B17: 1.3 Exterior Windows & Doors | D17: - | E17: Transport to Site | F17: 3.3 Kitchen | H17: - | I17: Roof sealing and heat... | J17: 5.2 Post Construction Clean-up
B18: - | C18: Manufacturing | F18: - | G18: Manufacturing | H18: - | I18: Exterior Painting
B19: - | C19: Installation

Sheet PRESENTATION
B2: ESTIMATE | D2: ACTUAL
B3: 261897.66 | D3: =SUM(D6,D12,D17,D23,D29) -> 261897.66
C6: PHASE ONE | D6: =SUM(D7:D9) -> 60718.038 | E6: PAID Invoice #1
C7: Container Purchase | D7: ='PROJECT ESTIMATE Wood Deck'!F65 -> 20400
C8: Structural Prep | D8: ='PROJECT ESTIMATE Wood Deck'!F66 -> 30718.038
C9: Exterior Windows & Doors | D9: ='PROJECT ESTIMATE Wood Deck'!F67/2 -> 9600
C12: PHASE TWO | D12: =SUM(D13:D14) -> 64237.075 | E12: PAID Invoice #2
C13: Exterior Windows & Doors | D13: ='PROJECT ESTIMATE Wood Deck'!F67/2 -> 9600
C14: Container Infrastructure | D14: ='PROJECT ESTIMATE Wood Deck'!F68 -> 54637.075
C17: PHASE THREE | D17: =SUM(D18:D20) -> 58066.497 | E17: PAID Invoice #2
C18: Interior Build | D18: ='PROJECT ESTIMATE Wood Deck'!F69 -> 34731.798
C19: Bathroom | D19: ='PROJECT ESTIMATE Wood Deck'!F70 -> 12921.864
C20: Kitchen | D20: ='PROJECT ESTIMATE Wood Deck'!F71/2 -> 10412.835
C23: PHASE FOUR | D23: =SUM(D24:D26) -> 57226.971
C24: Container Finishes | D24: ='PROJECT ESTIMATE Wood Deck'!F72 -> 24614.136
C25: Kitchen | D25: ='PROJECT ESTIMATE Wood Deck'!F71/2 -> 10412.835
C26: Container Installation | D26: ='PROJECT ESTIMATE Wood Deck'!F73 -> 22200
C29: PHASE FIVE | D29: =SUM(D30:D31) -> 21649.08
C30: Detailing | D30: ='PROJECT ESTIMATE Wood Deck'!F74 -> 19249.08
C31: Post Construction Cleanup | D31: ='PROJECT ESTIMATE Wood Deck'!F75 -> 2400

Sheet BUDGET
C1: Budget | E1: 0
C2: Product Build | D2: ='PROJECT ESTIMATE'!F64 -> 261897.66
C3: Ext & Add-on:
C4: ='PROJECT ESTIMATE'!C78 -> Foundation
C5: ='PROJECT ESTIMATE'!C79 -> Appliances Purchase
C6: ='PROJECT ESTIMATE'!C80 -> Solar Energy
C7: ='PROJECT ESTIMATE'!C81 -> Site Electric
C8: ='PROJECT ESTIMATE'!C82 -> Site Plumbing
C9: ='PROJECT ESTIMATE'!C83 -> Bio Garden
C10: ='PROJECT ESTIMATE'!C84 -> Pool
C11: ='PROJECT ESTIMATE'!C85 -> Steel Structure
C12: ='PROJECT ESTIMATE'!C86 -> Decking
C13: ='PROJECT ESTIMATE'!C87 -> Site Work
C14: ='PROJECT ESTIMATE'!C88 -> Furniture & Interior Elements
C15: ='PROJECT ESTIMATE'!C89 -> Windows & Doors (Exterior Structure)
C16: ='PROJECT ESTIMATE'!C90 -> Closet Build
C17: PM Site Visits
C18: Difference | E18: =E1-SUM(D2:D17) -> -261897.66

Sheet ESTIMATE OLD
B2: PROJECT SCOPE OVERVIEW
C5: CLIENT | D5: Enter Client Name | F5: DELIVERABLES:
C7: DATE | D7: =TODAY() -> 46043 | E7: FALSE | F7: Proposal
C9: VERSION | D9: Enter Version | E9: FALSE | F9: Design & Construction Docs
C11: PRODUCT TYPE | D11: Enter Type | E11: FALSE | F11: Product Delivery
C13: CLASSIFICATION:
C14: Paint by Numbers | D14: =VLOOKUP(C14,DATA!B35:D38,3,FALSE) -> [LOW RISK] KONTi and it's stakeholders are sure of what to do and how it is to be done. We feel confident on delivering the project early or under budget.
C16: PROJECT DESCRIPTION:
C17: The KONTi [ENTER MODEL] model was designed for a modular steel beam and post construction to be assembled on site. Design specs, construction requirements, and build costs are standard. THIS IS A COST PLUS ESTIMATE AND IS SUBJECT TO CHANGE.
C20: TOTAL PROJECT COST | F20: =SUM(E21:E24) -> 14036.15
C21: DESIGN AND DATA COLLECTION | E21: =F33 -> 0
C22: PERMITS & SERVICE FEES | E22: =F41 -> 14036.15
C23: CONTAINER(S) | E23: =SUM(F54,F61,F68,F75,F81) -> 0
C24: EXTERIOR & ADD-ONS | E24: =F88 -> 0
C26: CONSTRUCTION CONTINGENCY | F26: =SUM(E21:E24)*DATA!C23 -> 16141.573
C27: Designated amount of money within a construction budget that is set aside to cover any unforseen costs, risks, events, or changes in scope that may affect the project's cost over the course of its life. This money is on reserve and is not allocated to any specific area of work. It is a form of risk management used to avoid cutting costs in other areas to keep the project's schedule and quality commitments. This contingency is intended to cover additional costs that might occur due to factors like design changes, unexpected site conditions, weather delays, or other unforeseen circumstances.
B29: NOTE: THIS A COST-PLUS ESTIMATE AND IS SUBJECT TO CHANGE.
B31: DESIGN AND PERMITS:
C33: DESIGN AND DATA COLLECTION | F33: =SUM(E34:E37) -> 0
C34: Plans and Construction Documents | E34: 0
C35: Soil Study | E35: 0
C36: Survey and Topography | E36: 0
C37: Solar Energy Design | E37: 0
C41: PERMITS & SERVICE FEES | F41: =SUM(E42:E49) -> 14036.15
C42: Municipal Patent (5%) | E42: =SUM(F54,F61,F68,F75,F81,F88)*0.05 -> 0
C43: Permit Services | E43: 0
C44: Permit 1 (Ex. Categórica) | E44: 75 | F44: recuerda hacer el drop down aqui.. con REA/DEA
C45: Permit 2 (Construction) | E45: =SUM(F54,F61,F68,F75,F81,F88)*0.00635 -> 0
C46: Permit 3 (Use) | E46: 300
C47: Mandatory State Insurance | E47: =(DATA!C27/100)*5.65 -> 2661.15
C48: Liability Insurance | E48: 2000
C49: Construction Inspection Fee | E49: 9000
C50: Note: The projected costs have been calculated in line with the construction percentages stipulated by the Puerto Rico government and remain the exclusive obligation of the owner. KONTi Design assumes no liability for ultimate expenses ascertained by pertinent authorities and local bodies, contingent on the furnished documentation. Should the KONTi Design team need to secure financing for these outlays on behalf of the client, a coordination fee of 20% will be implemented, with the exception of the Municipal Patent, which will encompass a 10% coordination fee.
B52: CONSTRUCTION:
C54: CONTAINER(S): PHASE 1 | F54: =SUM(E55:E58) -> 0
C55: Container Purchase
C56: Structural Prep
C57: Exterior Windows & Doors (Purchase)
C58: Coordination Fee | E58: =SUM(E55:E57)*0.2 -> 0
C59: Includes: Purchase & Transport to shop; Cuts & Framing, Red Oxide , Extermination; Start of manufacturing of exterior windows & doors
...
